Workbook

Sheet Sheet1
A1: company | B1: Наименование | C1: year | D1: Дивиденд | E1: industry | F1: sum | G1: peer_sum | H1: payout | I1: payout_ratio | J1: abs | K1: pabs | L1: inc | M1: inc_ratio | N1: dec | O1: dec_ratio | P1: Size | Q1: Tangibility | R1: Sales_growth | S1: REBE | T1: ROA | U1: Leverage | V1: Psize | W1: PTangibility | X1: PSales_growth | Y1: PREBE | Z1: PROA | AA1: PLeverage
A2: GAZP | B2: =A2&" "& "IV" &" кв. "&C2 -> GAZP IV кв. 2025 | C2: 2025 | D2: =SUMIFS(Дивиденды!$C:$C,Дивиденды!$A:$A,A2,Дивиденды!$I:$I,C2) -> 0 | E2: 1 | F2: =D2 -> 0 | G2: =AVERAGEIFS($D:$D,$E:$E,E2,$C:$C,C2,$A:$A,"<>"&A2) -> 77.756667 | H2: =IF(D2>0,1,0) -> 0 | I2: =IFERROR((COUNTIFS($E:$E,E2,$C:$C,C2,$H:$H,1)-H2)/(COUNTIFS($E:$E,E2,$C:$C,C2)-1),0) -> 0.66666667 | J2: =IF(A3<>A2,"",IF(D2=D3,0,IF(AND(D3=0,D2<>0), 1,(D2-D3)/D3))) -> 0 | K2: =IFERROR(AVERAGEIFS($J:$J,$E:$E,E2,$C:$C,C2,$A:$A,"<>"&A2),"") -> -0.62296625 | L2: =IF(J2<>"",IF(J2>0,1,0),"") -> 0 | M2: =IFERROR(AVERAGEIFS($L:$L,$E:$E,E2,$C:$C,C2,$A:$A,"<>"&A2),"") -> 0 | N2: =IF(J2<>"",IF(J2<0,1,0),"") -> 0 | O2: =IFERROR(AVERAGEIFS($N:$N,$E:$E,E2,$C:$C,C2,$A:$A,"<>"&A2),"") -> 0.83333333 | P2: =IFERROR(LN('Дивиденды по годам'!I2),"") | Q2: =IFERROR('Дивиденды по годам'!G2/'Дивиденды по годам'!I2, "") | R2: =IFERROR(IF(AND('Дивиденды по годам'!N2<>"",'Дивиденды по годам'!U2<>"",'Дивиденды по годам'!U2<>0),'Дивиденды по годам'!N2/'Дивиденды по годам'!U2-1,""),"") | S2: =IFERROR(IF(AND('Дивиденды по годам'!L2<>"",'Дивиденды по годам'!I2<>"",'Дивиденды по годам'!J2<>"",'Дивиденды по годам'!K2<>"",('Дивиденды по годам'!I2-'Дивиденды по годам'!J2-'Дивиденды по годам'!K2)<>0),'Дивиденды по годам'!L2/('Дивиденды по годам'!I2-'Дивиденды по годам'!J2-'Дивиденды по годам'!K2),""),"") | T2: =IFERROR(IF(AND('Дивиденды по годам'!Q2<>"",'Дивиденды по годам'!I2<>"",'Дивиденды по годам'!V2<>"",('Дивиденды по годам'!I2+'Дивиденды по годам'!V2)<>0),'Дивиденды по годам'!Q2/(('Дивиденды по годам'!I2+'Дивиденды по годам'!V2)/2),""),"") | U2: =IFERROR(IF(AND('Дивиденды по годам'!J2<>"",'Дивиденды по годам'!K2<>"",'Дивиденды по годам'!M2<>"",'Дивиденды по годам'!M2<>0),('Дивиденды по годам'!J2+'Дивиденды по годам'!K2)/'Дивиденды по годам'!M2,""),"") | V2: {=IFERROR(AVERAGE(_xlfn._xlws.FILTER(P$2:P$1073,($C$2:$C$1073=$C2)*($E$2:$E$1073=$E2)*(ROW(P$2:P$1073)<>ROW(P2))*(P$2:P$1073<>""))),"")} -> 28.307188 | W2: {=IFERROR(AVERAGE(_xlfn._xlws.FILTER(Q$2:Q$1073,($C$2:$C$1073=$C2)*($E$2:$E$1073=$E2)*(ROW(Q$2:Q$1073)<>ROW(Q2))*(Q$2:Q$1073<>""))),"")} -> 0.53419344 | X2: {=IFERROR(AVERAGE(_xlfn._xlws.FILTER(R$2:R$1073,($C$2:$C$1073=$C2)*($E$2:$E$1073=$E2)*(ROW(R$2:R$1073)<>ROW(R2))*(R$2:R$1073<>""))),"")} -> -0.25128972 | Y2: {=IFERROR(AVERAGE(_xlfn._xlws.FILTER(S$2:S$1073,($C$2:$C$1073=$C2)*($E$2:$E$1073=$E2)*(ROW(S$2:S$1073)<>ROW(S2))*(S$2:S$1073<>""))),"")} -> 0.71039154 | Z2: {=IFERROR(AVERAGE(_xlfn._xlws.FILTER(T$2:T$1073,($C$2:$C$1073=$C2)*($E$2:$E$1073=$E2)*(ROW(T$2:T$1073)<>ROW(T2))*(T$2:T$1073<>""))),"")} -> 0.011099136 | AA2: {=IFERROR(AVERAGE(_xlfn._xlws.FILTER(U$2:U$1073,($C$2:$C$1073=$C2)*($E$2:$E$1073=$E2)*(ROW(U$2:U$1073)<>ROW(U2))*(U$2:U$1073<>""))),"")} -> 0.71283761
A3: GAZP | B3: =A3&" "& "IV" &" кв. "&C3 -> GAZP IV кв. 2024 | C3: 2024 | D3: =SUMIFS(Дивиденды!$C:$C,Дивиденды!$A:$A,A3,Дивиденды!$I:$I,C3) -> 0 | E3: 1 | F3: =D3 -> 0 | G3: =AVERAGEIFS($D:$D,$E:$E,E3,$C:$C,C3,$A:$A,"<>"&A3) -> 214.65 | H3: =IF(D3>0,1,0) -> 0 | I3: =IFERROR((COUNTIFS($E:$E,E3,$C:$C,C3,$H:$H,1)-H3)/(COUNTIFS($E:$E,E3,$C:$C,C3)-1),0) -> 0.83333333 | J3: =IF(A4<>A3,"",IF(D3=D4,0,IF(AND(D4=0,D3<>0), 1,(D3-D4)/D4))) -> 0 | K3: =IFERROR(AVERAGEIFS($J:$J,$E:$E,E3,$C:$C,C3,$A:$A,"<>"&A3),"") -> 0.033213968 | L3: =IF(J3<>"",IF(J3>0,1,0),"") -> 0 | M3: =IFERROR(AVERAGEIFS($L:$L,$E:$E,E3,$C:$C,C3,$A:$A,"<>"&A3),"") -> 0.66666667 | N3: =IF(J3<>"",IF(J3<0,1,0),"") -> 0 | O3: =IFERROR(AVERAGEIFS($N:$N,$E:$E,E3,$C:$C,C3,$A:$A,"<>"&A3),"") -> 0.16666667 | P3: =IFERROR(LN('Дивиденды по годам'!I3),"") -> 31.055227 | Q3: =IFERROR('Дивиденды по годам'!G3/'Дивиденды по годам'!I3, "") -> 0.67690981 | R3: =IFERROR(IF(AND('Дивиденды по годам'!N3<>"",'Дивиденды по годам'!U3<>"",'Дивиденды по годам'!U3<>0),'Дивиденды по годам'!N3/'Дивиденды по годам'!U3-1,""),"") -> 0.25438004 | S3: =IFERROR(IF(AND('Дивиденды по годам'!L3<>"",'Дивиденды по годам'!I3<>"",'Дивиденды по годам'!J3<>"",'Дивиденды по годам'!K3<>"",('Дивиденды по годам'!I3-'Дивиденды по годам'!J3-'Дивиденды по годам'!K3)<>0),'Дивиденды по годам'!L3/('Дивиденды по годам'!I3-'Дивиденды по годам'!J3-'Дивиденды по годам'!K3),""),"") -> 0.88491057 | T3: =IFERROR(IF(AND('Дивиденды по годам'!Q3<>"",'Дивиденды по годам'!I3<>"",'Дивиденды по годам'!V3<>"",('Дивиденды по годам'!I3+'Дивиденды по годам'!V3)<>0),'Дивиденды по годам'!Q3/(('Дивиденды по годам'!I3+'Дивиденды по годам'!V3)/2),""),"") -> 0.04439204 | U3: =IFERROR(IF(AND('Дивиденды по годам'!J3<>"",'Дивиденды по годам'!K3<>"",'Дивиденды по годам'!M3<>"",'Дивиденды по годам'!M3<>0),('Дивиденды по годам'!J3+'Дивиденды по годам'!K3)/'Дивиденды по годам'!M3,""),"") -> 0.73819835 | V3: {=IFERROR(AVERAGE(_xlfn._xlws.FILTER(P$2:P$1073,($C$2:$C$1073=$C3)*($E$2:$E$1073=$E3)*(ROW(P$2:P$1073)<>ROW(P3))*(P$2:P$1073<>""))),"")} -> 28.89571 | W3: {=IFERROR(AVERAGE(_xlfn._xlws.FILTER(Q$2:Q$1073,($C$2:$C$1073=$C3)*($E$2:$E$1073=$E3)*(ROW(Q$2:Q$1073)<>ROW(Q3))*(Q$2:Q$1073<>""))),"")} -> 0.51199198 | X3: {=IFERROR(AVERAGE(_xlfn._xlws.FILTER(R$2:R$1073,($C$2:$C$1073=$C3)*($E$2:$E$1073=$E3)*(ROW(R$2:R$1073)<>ROW(R3))*(R$2:R$1073<>""))),"")} -> 0.17118061 | Y3: {=IFERROR(AVERAGE(_xlfn._xlws.FILTER(S$2:S$1073,($C$2:$C$1073=$C3)*($E$2:$E$1073=$E3)*(ROW(S$2:S$1073)<>ROW(S3))*(S$2:S$1073<>""))),"")} -> 0.79852548 | Z3: {=IFERROR(AVERAGE(_xlfn._xlws.FILTER(T$2:T$1073,($C$2:$C$1073=$C3)*($E$2:$E$1073=$E3)*(ROW(T$2:T$1073)<>ROW(T3))*(T$2:T$1073<>""))),"")} -> 0.12177692 | AA3: {=IFERROR(AVERAGE(_xlfn._xlws.FILTER(U$2:U$1073,($C$2:$C$1073=$C3)*($E$2:$E$1073=$E3)*(ROW(U$2:U$1073)<>ROW(U3))*(U$2:U$1073<>""))),"")} -> 0.85190113
A4: GAZP | B4: =A4&" "& "IV" &" кв. "&C4 -> GAZP IV кв. 2023 | C4: 2023 | D4: =SUMIFS(Дивиденды!$C:$C,Дивиденды!$A:$A,A4,Дивиденды!$I:$I,C4) -> 0 | E4: 1 | F4: =D4 -> 0 | G4: =AVERAGEIFS($D:$D,$E:$E,E4,$C:$C,C4,$A:$A,"<>"&A4) -> 195.35 | H4: =IF(D4>0,1,0) -> 0 | I4: =IFERROR((COUNTIFS($E:$E,E4,$C:$C,C4,$H:$H,1)-H4)/(COUNTIFS($E:$E,E4,$C:$C,C4)-1),0) -> 0.83333333 | J4: =IF(A5<>A4,"",IF(D4=D5,0,IF(AND(D5=0,D4<>0), 1,(D4-D5)/D5))) -> -1 | K4: =IFERROR(AVERAGEIFS($J:$J,$E:$E,E4,$C:$C,C4,$A:$A,"<>"&A4),"") -> 0.07318505 | L4: =IF(J4<>"",IF(J4>0,1,0),"") -> 0 | M4: =IFERROR(AVERAGEIFS($L:$L,$E:$E,E4,$C:$C,C4,$A:$A,"<>"&A4),"") -> 0.5 | N4: =IF(J4<>"",IF(J4<0,1,0),"") -> 1 | O4: =IFERROR(AVERAGEIFS($N:$N,$E:$E,E4,$C:$C,C4,$A:$A,"<>"&A4),"") -> 0.33333333 | P4: =IFERROR(LN('Дивиденды по годам'!I4),"") -> 30.988397 | Q4: =IFERROR('Дивиденды по годам'!G4/'Дивиденды по годам'!I4, "") -> 0.64206898 | R4: =IFERROR(IF(AND('Дивиденды по годам'!N4<>"",'Дивиденды по годам'!U4<>"",'Дивиденды по годам'!U4<>0),'Дивиденды по годам'!N4/'Дивиденды по годам'!U4-1,""),"") -> -0.26830096 | S4: =IFERROR(IF(AND('Дивиденды по годам'!L4<>"",'Дивиденды по годам'!I4<>"",'Дивиденды по годам'!J4<>"",'Дивиденды по годам'!K4<>"",('Дивиденды по годам'!I4-'Дивиденды по годам'!J4-'Дивиденды по годам'!K4)<>0),'Дивиденды по годам'!L4/('Дивиденды по годам'!I4-'Дивиденды по годам'!J4-'Дивиденды по годам'!K4),""),"") -> 0.88690206 | T4: =IFERROR(IF(AND('Дивиденды по годам'!Q4<>"",'Дивиденды по годам'!I4<>"",'Дивиденды по годам'!V4<>"",('Дивиденды по годам'!I4+'Дивиденды по годам'!V4)<>0),'Дивиденды по годам'!Q4/(('Дивиденды по годам'!I4+'Дивиденды по годам'!V4)/2),""),"") -> -0.021263586 | U4: =IFERROR(IF(AND('Дивиденды по годам'!J4<>"",'Дивиденды по годам'!K4<>"",'Дивиденды по годам'!M4<>"",'Дивиденды по годам'!M4<>0),('Дивиденды по годам'!J4+'Дивиденды по годам'!K4)/'Дивиденды по годам'!M4,""),"") -> 0.74522866 | V4: {=IFERROR(AVERAGE(_xlfn._xlws.FILTER(P$2:P$1073,($C$2:$C$1073=$C4)*($E$2:$E$1073=$E4)*(ROW(P$2:P$1073)<>ROW(P4))*(P$2:P$1073<>""))),"")} -> 28.950488 | W4: {=IFERROR(AVERAGE(_xlfn._xlws.FILTER(Q$2:Q$1073,($C$2:$C$1073=$C4)*($E$2:$E$1073=$E4)*(ROW(Q$2:Q$1073)<>ROW(Q4))*(Q$2:Q$1073<>""))),"")} -> 0.47348976 | X4: {=IFERROR(AVERAGE(_xlfn._xlws.FILTER(R$2:R$1073,($C$2:$C$1073=$C4)*($E$2:$E$1073=$E4)*(ROW(R$2:R$1073)<>ROW(R4))*(R$2:R$1073<>""))),"")} -> -0.037500665 | Y4: {=IFERROR(AVERAGE(_xlfn._xlws.FILTER(S$2:S$1073,($C$2:$C$1073=$C4)*($E$2:$E$1073=$E4)*(ROW(S$2:S$1073)<>ROW(S4))*(S$2:S$1073<>""))),"")} -> 0.80302193 | Z4: {=IFERROR(AVERAGE(_xlfn._xlws.FILTER(T$2:T$1073,($C$2:$C$1073=$C4)*($E$2:$E$1073=$E4)*(ROW(T$2:T$1073)<>ROW(T4))*(T$2:T$1073<>""))),"")} -> 0.11841775 | AA4: {=IFERROR(AVERAGE(_xlfn._xlws.FILTER(U$2:U$1073,($C$2:$C$1073=$C4)*($E$2:$E$1073=$E4)*(ROW(U$2:U$1073)<>ROW(U4))*(U$2:U$1073<>""))),"")} -> 0.83818778
A5: GAZP | B5: =A5&" "& "IV" &" кв. "&C5 -> GAZP IV кв. 2022 | C5: 2022 | D5: =SUMIFS(Дивиденды!$C:$C,Дивиденды!$A:$A,A5,Дивиденды!$I:$I,C5) -> 51.03 | E5: 1 | F5: =D5 -> 51.03 | G5: =AVERAGEIFS($D:$D,$E:$E,E5,$C:$C,C5,$A:$A,"<>"&A5) -> 240.50333 | H5: =IF(D5>0,1,0) -> 1 | I5: =IFERROR((COUNTIFS($E:$E,E5,$C:$C,C5,$H:$H,1)-H5)/(COUNTIFS($E:$E,E5,$C:$C,C5)-1),0) -> 0.83333333 | J5: =IF(A6<>A5,"",IF(D5=D6,0,IF(AND(D6=0,D5<>0), 1,(D5-D6)/D6))) -> 1 | K5: =IFERROR(AVERAGEIFS($J:$J,$E:$E,E5,$C:$C,C5,$A:$A,"<>"&A5),"") -> 0.59952004 | L5: =IF(J5<>"",IF(J5>0,1,0),"") -> 1 | M5: =IFERROR(AVERAGEIFS($L:$L,$E:$E,E5,$C:$C,C5,$A:$A,"<>"&A5),"") -> 0.5 | N5: =IF(J5<>"",IF(J5<0,1,0),"") -> 0 | O5: =IFERROR(AVERAGEIFS($N:$N,$E:$E,E5,$C:$C,C5,$A:$A,"<>"&A5),"") -> 0.16666667 | P5: =IFERROR(LN('Дивиденды по годам'!I5),"") -> 30.894064 | Q5: =IFERROR('Дивиденды по годам'!G5/'Дивиденды по годам'!I5, "") -> 0.66665802 | R5: =IFERROR(IF(AND('Дивиденды по годам'!N5<>"",'Дивиденды по годам'!U5<>"",'Дивиденды по годам'!U5<>0),'Дивиденды по годам'!N5/'Дивиденды по годам'!U5-1,""),"") -> 0.13988357 | S5: =IFERROR(IF(AND('Дивиденды по годам'!L5<>"",'Дивиденды по годам'!I5<>"",'Дивиденды по годам'!J5<>"",'Дивиденды по годам'!K5<>"",('Дивиденды по годам'!I5-'Дивиденды по годам'!J5-'Дивиденды по годам'!K5)<>0),'Дивиденды по годам'!L5/('Дивиденды по годам'!I5-'Дивиденды по годам'!J5-'Дивиденды по годам'!K5),""),"") -> 0.9197466 | T5: =IFERROR(IF(AND('Дивиденды по годам'!Q5<>"",'Дивиденды по годам'!I5<>"",'Дивиденды по годам'!V5<>"",('Дивиденды по годам'!I5+'Дивиденды по годам'!V5)<>0),'Дивиденды по годам'!Q5/(('Дивиденды по годам'!I5+'Дивиденды по годам'!V5)/2),""),"") -> 0.04933207 | U5: =IFERROR(IF(AND('Дивиденды по годам'!J5<>"",'Дивиденды по годам'!K5<>"",'Дивиденды по годам'!M5<>"",'Дивиденды по годам'!M5<>0),('Дивиденды по годам'!J5+'Дивиденды по годам'!K5)/'Дивиденды по годам'!M5,""),"") -> 0.58878604 | V5: {=IFERROR(AVERAGE(_xlfn._xlws.FILTER(P$2:P$1073,($C$2:$C$1073=$C5)*($E$2:$E$1073=$E5)*(ROW(P$2:P$1073)<>ROW(P5))*(P$2:P$1073<>""))),"")} -> 28.005023 | W5: {=IFERROR(AVERAGE(_xlfn._xlws.FILTER(Q$2:Q$1073,($C$2:$C$1073=$C5)*($E$2:$E$1073=$E5)*(ROW(Q$2:Q$1073)<>ROW(Q5))*(Q$2:Q$1073<>""))),"")} -> 0.45949876 | X5: {=IFERROR(AVERAGE(_xlfn._xlws.FILTER(R$2:R$1073,($C$2:$C$1073=$C5)*($E$2:$E$1073=$E5)*(ROW(R$2:R$1073)<>ROW(R5))*(R$2:R$1073<>""))),"")} -> 0.1038114 | Y5: {=IFERROR(AVERAGE(_xlfn._xlws.FILTER(S$2:S$1073,($C$2:$C$1073=$C5)*($E$2:$E$1073=$E5)*(ROW(S$2:S$1073)<>ROW(S5))*(S$2:S$1073<>""))),"")} -> 0.78172804 | Z5: {=IFERROR(AVERAGE(_xlfn._xlws.FILTER(T$2:T$1073,($C$2:$C$1073=$C5)*($E$2:$E$1073=$E5)*(ROW(T$2:T$1073)<>ROW(T5))*(T$2:T$1073<>""))),"")} -> 0.12952165 | AA5: {=IFERROR(AVERAGE(_xlfn._xlws.FILTER(U$2:U$1073,($C$2:$C$1073=$C5)*($E$2:$E$1073=$E5)*(ROW(U$2:U$1073)<>ROW(U5))*(U$2:U$1073<>""))),"")} -> 0.8837483
A6: GAZP | B6: =A6&" "& "IV" &" кв. "&C6 -> GAZP IV кв. 2021 | C6: 2021 | D6: =SUMIFS(Дивиденды!$C:$C,Дивиденды!$A:$A,A6,Дивиденды!$I:$I,C6) -> 0 | E6: 1 | F6: =D6 -> 0 | G6: =AVERAGEIFS($D:$D,$E:$E,E6,$C:$C,C6,$A:$A,"<>"&A6) -> 82.756667 | H6: =IF(D6>0,1,0) -> 0 | I6: =IFERROR((COUNTIFS($E:$E,E6,$C:$C,C6,$H:$H,1)-H6)/(COUNTIFS($E:$E,E6,$C:$C,C6)-1),0) -> 0.83333333 | J6: =IF(A7<>A6,"",IF(D6=D7,0,IF(AND(D7=0,D6<>0), 1,(D6-D7)/D7))) -> -1 | K6: =IFERROR(AVERAGEIFS($J:$J,$E:$E,E6,$C:$C,C6,$A:$A,"<>"&A6),"") -> 1.2307909 | L6: =IF(J6<>"",IF(J6>0,1,0),"") -> 0 | M6: =IFERROR(AVERAGEIFS($L:$L,$E:$E,E6,$C:$C,C6,$A:$A,"<>"&A6),"") -> 0.83333333 | N6: =IF(J6<>"",IF(J6<0,1,0),"") -> 1 | O6: =IFERROR(AVERAGEIFS($N:$N,$E:$E,E6,$C:$C,C6,$A:$A,"<>"&A6),"") -> 0 | P6: =IFERROR(LN('Дивиденды по годам'!I6),"") -> 30.928606 | Q6: =IFERROR('Дивиденды по годам'!G6/'Дивиденды по годам'!I6, "") -> 0.61646121 | R6: =IFERROR(IF(AND('Дивиденды по годам'!N6<>"",'Дивиденды по годам'!U6<>"",'Дивиденды по годам'!U6<>0),'Дивиденды по годам'!N6/'Дивиденды по годам'!U6-1,""),"") -> 0.62006761 | S6: =IFERROR(IF(AND('Дивиденды по годам'!L6<>"",'Дивиденды по годам'!I6<>"",'Дивиденды по годам'!J6<>"",'Дивиденды по годам'!K6<>"",('Дивиденды по годам'!I6-'Дивиденды по годам'!J6-'Дивиденды по годам'!K6)<>0),'Дивиденды по годам'!L6/('Дивиденды по годам'!I6-'Дивиденды по годам'!J6-'Дивиденды по годам'!K6),""),"") -> 0.92570438 | T6: =IFERROR(IF(AND('Дивиденды по годам'!Q6<>"",'Дивиденды по годам'!I6<>"",'Дивиденды по годам'!V6<>"",('Дивиденды по годам'!I6+'Дивиденды по годам'!V6)<>0),'Дивиденды по годам'!Q6/(('Дивиденды по годам'!I6+'Дивиденды по годам'!V6)/2),""),"") -> 0.08567901 | U6: =IFERROR(IF(AND('Дивиденды по годам'!J6<>"",'Дивиденды по годам'!K6<>"",'Дивиденды по годам'!M6<>"",'Дивиденды по годам'!M6<>0),('Дивиденды по годам'!J6+'Дивиденды по годам'!K6)/'Дивиденды по годам'!M6,""),"") -> 0.60359905 | V6: {=IFERROR(AVERAGE(_xlfn._xlws.FILTER(P$2:P$1073,($C$2:$C$1073=$C6)*($E$2:$E$1073=$E6)*(ROW(P$2:P$1073)<>ROW(P6))*(P$2:P$1073<>""))),"")} -> 28.588015 | W6: {=IFERROR(AVERAGE(_xlfn._xlws.FILTER(Q$2:Q$1073,($C$2:$C$1073=$C6)*($E$2:$E$1073=$E6)*(ROW(Q$2:Q$1073)<>ROW(Q6))*(Q$2:Q$1073<>""))),"")} -> 0.54592305 | X6: {=IFERROR(AVERAGE(_xlfn._xlws.FILTER(R$2:R$1073,($C$2:$C$1073=$C6)*($E$2:$E$1073=$E6)*(ROW(R$2:R$1073)<>ROW(R6))*(R$2:R$1073<>""))),"")} -> 0.71962064 | Y6: {=IFERROR(AVERAGE(_xlfn._xlws.FILTER(S$2:S$1073,($C$2:$C$1073=$C6)*($E$2:$E$1073=$E6)*(ROW(S$2:S$1073)<>ROW(S6))*(S$2:S$1073<>""))),"")} -> 0.78164523 | Z6: {=IFERROR(AVERAGE(_xlfn._xlws.FILTER(T$2:T$1073,($C$2:$C$1073=$C6)*($E$2:$E$1073=$E6)*(ROW(T$2:T$1073)<>ROW(T6))*(T$2:T$1073<>""))),"")} -> 0.12893486 | AA6: {=IFERROR(AVERAGE(_xlfn._xlws.FILTER(U$2:U$1073,($C$2:$C$1073=$C6)*($E$2:$E$1073=$E6)*(ROW(U$2:U$1073)<>ROW(U6))*(U$2:U$1073<>""))),"")} -> 1.1281548
A7: GAZP | B7: =A7&" "& "IV" &" кв. "&C7 -> GAZP IV кв. 2020 | C7: 2020 | D7: =SUMIFS(Дивиденды!$C:$C,Дивиденды!$A:$A,A7,Дивиденды!$I:$I,C7) -> 12.55 | E7: 1 | F7: =D7 -> 12.55 | G7: =AVERAGEIFS($D:$D,$E:$E,E7,$C:$C,C7,$A:$A,"<>"&A7) -> 54.073333 | H7: =IF(D7>0,1,0) -> 1 | I7: =IFERROR((COUNTIFS($E:$E,E7,$C:$C,C7,$H:$H,1)-H7)/(COUNTIFS($E:$E,E7,$C:$C,C7)-1),0) -> 0.83333333 | J7: =IF(A8<>A7,"",IF(D7=D8,0,IF(AND(D8=0,D7<>0), 1,(D7-D8)/D8))) -> -0.17650919 | K7: =IFERROR(AVERAGEIFS($J:$J,$E:$E,E7,$C:$C,C7,$A:$A,"<>"&A7),"") -> -0.29877017 | L7: =IF(J7<>"",IF(J7>0,1,0),"") -> 0 | M7: =IFERROR(AVERAGEIFS($L:$L,$E:$E,E7,$C:$C,C7,$A:$A,"<>"&A7),"") -> 0.33333333 | N7: =IF(J7<>"",IF(J7<0,1,0),"") -> 1 | O7: =IFERROR(AVERAGEIFS($N:$N,$E:$E,E7,$C:$C,C7,$A:$A,"<>"&A7),"") -> 0.5 | P7: =IFERROR(LN('Дивиденды по годам'!I7),"") -> 30.781712 | Q7: =IFERROR('Дивиденды по годам'!G7/'Дивиденды по годам'!I7, "") -> 0.68957552 | R7: =IFERROR(IF(AND('Дивиденды по годам'!N7<>"",'Дивиденды по годам'!U7<>"",'Дивиденды по годам'!U7<>0),'Дивиденды по годам'!N7/'Дивиденды по годам'!U7-1,""),"") -> -0.17469058 | S7: =IFERROR(IF(AND('Дивиденды по годам'!L7<>"",'Дивиденды по годам'!I7<>"",'Дивиденды по годам'!J7<>"",'Дивиденды по годам'!K7<>"",('Дивиденды по годам'!I7-'Дивиденды по годам'!J7-'Дивиденды по годам'!K7)<>0),'Дивиденды по годам'!L7/('Дивиденды по годам'!I7-'Дивиденды по годам'!J7-'Дивиденды по годам'!K7),""),"") -> 0.92655943 | T7: =IFERROR(IF(AND('Дивиденды по годам'!Q7<>"",'Дивиденды по годам'!I7<>"",'Дивиденды по годам'!V7<>"",('Дивиденды по годам'!I7+'Дивиденды по годам'!V7)<>0),'Дивиденды по годам'!Q7/(('Дивиденды по годам'!I7+'Дивиденды по годам'!V7)/2),""),"") -> 0.0071806644 | U7: =IFERROR(IF(AND('Дивиденды по годам'!J7<>"",'Дивиденды по годам'!K7<>"",'Дивиденды по годам'!M7<>"",'Дивиденды по годам'!M7<>0),('Дивиденды по годам'!J7+'Дивиденды по годам'!K7)/'Дивиденды по годам'!M7,""),"") -> 0.57734601 | V7: {=IFERROR(AVERAGE(_xlfn._xlws.FILTER(P$2:P$1073,($C$2:$C$1073=$C7)*($E$2:$E$1073=$E7)*(ROW(P$2:P$1073)<>ROW(P7))*(P$2:P$1073<>""))),"")} -> 28.624109 | W7: {=IFERROR(AVERAGE(_xlfn._xlws.FILTER(Q$2:Q$1073,($C$2:$C$1073=$C7)*($E$2:$E$1073=$E7)*(ROW(Q$2:Q$1073)<>ROW(Q7))*(Q$2:Q$1073<>""))),"")} -> 0.5371219 | X7: {=IFERROR(AVERAGE(_xlfn._xlws.FILTER(R$2:R$1073,($C$2:$C$1073=$C7)*($E$2:$E$1073=$E7)*(ROW(R$2:R$1073)<>ROW(R7))*(R$2:R$1073<>""))),"")} -> -0.27049471 | Y7: {=IFERROR(AVERAGE(_xlfn._xlws.FILTER(S$2:S$1073,($C$2:$C$1073=$C7)*($E$2:$E$1073=$E7)*(ROW(S$2:S$1073)<>ROW(S7))*(S$2:S$1073<>""))),"")} -> 0.74822584 | Z7: {=IFERROR(AVERAGE(_xlfn._xlws.FILTER(T$2:T$1073,($C$2:$C$1073=$C7)*($E$2:$E$1073=$E7)*(ROW(T$2:T$1073)<>ROW(T7))*(T$2:T$1073<>""))),"")} -> 0.032136749 | AA7: {=IFERROR(AVERAGE(_xlfn._xlws.FILTER(U$2:U$1073,($C$2:$C$1073=$C7)*($E$2:$E$1073=$E7)*(ROW(U$2:U$1073)<>ROW(U7))*(U$2:U$1073<>""))),"")} -> 1.2967729
A8: GAZP | B8: =A8&" "& "IV" &" кв. "&C8 -> GAZP IV кв. 2019 | C8: 2019 | D8: =SUMIFS(Дивиденды!$C:$C,Дивиденды!$A:$A,A8,Дивиденды!$I:$I,C8) -> 15.24 | E8: 1 | F8: =D8 -> 15.24 | G8: =AVERAGEIFS($D:$D,$E:$E,E8,$C:$C,C8,$A:$A,"<>"&A8) -> 112.14333 | H8: =IF(D8>0,1,0) -> 1 | I8: =IFERROR((COUNTIFS($E:$E,E8,$C:$C,C8,$H:$H,1)-H8)/(COUNTIFS($E:$E,E8,$C:$C,C8)-1),0) -> 0.83333333 | J8: =IF(A9<>A8,"",IF(D8=D9,0,IF(AND(D9=0,D8<>0), 1,(D8-D9)/D9))) -> -0.082480433 | K8: =IFERROR(AVERAGEIFS($J:$J,$E:$E,E8,$C:$C,C8,$A:$A,"<>"&A8),"") -> 0.24288945 | L8: =IF(J8<>"",IF(J8>0,1,0),"") -> 0 | M8: =IFERROR(AVERAGEIFS($L:$L,$E:$E,E8,$C:$C,C8,$A:$A,"<>"&A8),"") -> 0.5 | N8: =IF(J8<>"",IF(J8<0,1,0),"") -> 1 | O8: =IFERROR(AVERAGEIFS($N:$N,$E:$E,E8,$C:$C,C8,$A:$A,"<>"&A8),"") -> 0.16666667 | P8: =IFERROR(LN('Дивиденды по годам'!I8),"") -> 30.716701 | Q8: =IFERROR('Дивиденды по годам'!G8/'Дивиденды по годам'!I8, "") -> 0.67892385 | R8: =IFERROR(IF(AND('Дивиденды по годам'!N8<>"",'Дивиденды по годам'!U8<>"",'Дивиденды по годам'!U8<>0),'Дивиденды по годам'!N8/'Дивиденды по годам'!U8-1,""),"") -> -0.068645653 | S8: =IFERROR(IF(AND('Дивиденды по годам'!L8<>"",'Дивиденды по годам'!I8<>"",'Дивиденды по годам'!J8<>"",'Дивиденды по годам'!K8<>"",('Дивиденды по годам'!I8-'Дивиденды по годам'!J8-'Дивиденды по годам'!K8)<>0),'Дивиденды по годам'!L8/('Дивиденды по годам'!I8-'Дивиденды по годам'!J8-'Дивиденды по годам'!K8),""),"") -> 0.94282055 | T8: =IFERROR(IF(AND('Дивиденды по годам'!Q8<>"",'Дивиденды по годам'!I8<>"",'Дивиденды по годам'!V8<>"",('Дивиденды по годам'!I8+'Дивиденды по годам'!V8)<>0),'Дивиденды по годам'!Q8/(('Дивиденды по годам'!I8+'Дивиденды по годам'!V8)/2),""),"") -> 0.059472199 | U8: =IFERROR(IF(AND('Дивиденды по годам'!J8<>"",'Дивиденды по годам'!K8<>"",'Дивиденды по годам'!M8<>"",'Дивиденды по годам'!M8<>0),('Дивиденды по годам'!J8+'Дивиденды по годам'!K8)/'Дивиденды по годам'!M8,""),"") -> 0.49718231 | V8: {=IFERROR(AVERAGE(_xlfn._xlws.FILTER(P$2:P$1073,($C$2:$C$1073=$C8)*($E$2:$E$1073=$E8)*(ROW(P$2:P$1073)<>ROW(P8))*(P$2:P$1073<>""))),"")} -> 28.572217 | W8: {=IFERROR(AVERAGE(_xlfn._xlws.FILTER(Q$2:Q$1073,($C$2:$C$1073=$C8)*($E$2:$E$1073=$E8)*(ROW(Q$2:Q$1073)<>ROW(Q8))*(Q$2:Q$1073<>""))),"")} -> 0.51462951 | X8: {=IFERROR(AVERAGE(_xlfn._xlws.FILTER(R$2:R$1073,($C$2:$C$1073=$C8)*($E$2:$E$1073=$E8)*(ROW(R$2:R$1073)<>ROW(R8))*(R$2:R$1073<>""))),"")} -> 0.025367391 | Y8: {=IFERROR(AVERAGE(_xlfn._xlws.FILTER(S$2:S$1073,($C$2:$C$1073=$C8)*($E$2:$E$1073=$E8)*(ROW(S$2:S$1073)<>ROW(S8))*(S$2:S$1073<>""))),"")} -> 0.82043004 | Z8: {=IFERROR(AVERAGE(_xlfn._xlws.FILTER(T$2:T$1073,($C$2:$C$1073=$C8)*($E$2:$E$1073=$E8)*(ROW(T$2:T$1073)<>ROW(T8))*(T$2:T$1073<>""))),"")} -> 0.16320282 | AA8: {=IFERROR(AVERAGE(_xlfn._xlws.FILTER(U$2:U$1073,($C$2:$C$1073=$C8)*($E$2:$E$1073=$E8)*(ROW(U$2:U$1073)<>ROW(U8))*(U$2:U$1073<>""))),"")} -> 0.95146752
A9: GAZP | B9: =A9&" "& "IV" &" кв. "&C9 -> GAZP IV кв. 2018 | C9: 2018 | D9: =SUMIFS(Дивиденды!$C:$C,Дивиденды!$A:$A,A9,Дивиденды!$I:$I,C9) -> 16.61 | E9: 1 | F9: =D9 -> 16.61 | G9: =AVERAGEIFS($D:$D,$E:$E,E9,$C:$C,C9,$A:$A,"<>"&A9) -> 64.588333 | H9: =IF(D9>0,1,0) -> 1 | I9: =IFERROR((COUNTIFS($E:$E,E9,$C:$C,C9,$H:$H,1)-H9)/(COUNTIFS($E:$E,E9,$C:$C,C9)-1),0) -> 0.83333333 | J9: =IF(A10<>A9,"",IF(D9=D10,0,IF(AND(D10=0,D9<>0), 1,(D9-D10)/D10))) -> 1.0659204 | K9: =IFERROR(AVERAGEIFS($J:$J,$E:$E,E9,$C:$C,C9,$A:$A,"<>"&A9),"") -> 0.58403361 | L9: =IF(J9<>"",IF(J9>0,1,0),"") -> 1 | M9: =IFERROR(AVERAGEIFS($L:$L,$E:$E,E9,$C:$C,C9,$A:$A,"<>"&A9),"") -> 0.66666667 | N9: =IF(J9<>"",IF(J9<0,1,0),"") -> 0 | O9: =IFERROR(AVERAGEIFS($N:$N,$E:$E,E9,$C:$C,C9,$A:$A,"<>"&A9),"") -> 0 | P9: =IFERROR(LN('Дивиденды по годам'!I9),"") -> 30.666476 | Q9: =IFERROR('Дивиденды по годам'!G9/'Дивиденды по годам'!I9, "") -> 0.66358203 | R9: =IFERROR(IF(AND('Дивиденды по годам'!N9<>"",'Дивиденды по годам'!U9<>"",'Дивиденды по годам'!U9<>0),'Дивиденды по годам'!N9/'Дивиденды по годам'!U9-1,""),"") -> 0.25633934 | S9: =IFERROR(IF(AND('Дивиденды по годам'!L9<>"",'Дивиденды по годам'!I9<>"",'Дивиденды по годам'!J9<>"",'Дивиденды по годам'!K9<>"",('Дивиденды по годам'!I9-'Дивиденды по годам'!J9-'Дивиденды по годам'!K9)<>0),'Дивиденды по годам'!L9/('Дивиденды по годам'!I9-'Дивиденды по годам'!J9-'Дивиденды по годам'!K9),""),"") -> 0.95895668 | T9: =IFERROR(IF(AND('Дивиденды по годам'!Q9<>"",'Дивиденды по годам'!I9<>"",'Дивиденды по годам'!V9<>"",('Дивиденды по годам'!I9+'Дивиденды по годам'!V9)<>0),'Дивиденды по годам'!Q9/(('Дивиденды по годам'!I9+'Дивиденды по годам'!V9)/2),""),"") -> 0.078311239 | U9: =IFERROR(IF(AND('Дивиденды по годам'!J9<>"",'Дивиденды по годам'!K9<>"",'Дивиденды по годам'!M9<>"",'Дивиденды по годам'!M9<>0),('Дивиденды по годам'!J9+'Дивиденды по годам'!K9)/'Дивиденды по годам'!M9,""),"") -> 0.5106133 | V9: {=IFERROR(AVERAGE(_xlfn._xlws.FILTER(P$2:P$1073,($C$2:$C$1073=$C9)*($E$2:$E$1073=$E9)*(ROW(P$2:P$1073)<>ROW(P9))*(P$2:P$1073<>""))),"")} -> 28.458498 | W9: {=IFERROR(AVERAGE(_xlfn._xlws.FILTER(Q$2:Q$1073,($C$2:$C$1073=$C9)*($E$2:$E$1073=$E9)*(ROW(Q$2:Q$1073)<>ROW(Q9))*(Q$2:Q$1073<>""))),"")} -> 0.50857093 | X9: {=IFERROR(AVERAGE(_xlfn._xlws.FILTER(R$2:R$1073,($C$2:$C$1073=$C9)*($E$2:$E$1073=$E9)*(ROW(R$2:R$1073)<>ROW(R9))*(R$2:R$1073<>""))),"")} -> 0.36447021 | Y9: {=IFERROR(AVERAGE(_xlfn._xlws.FILTER(S$2:S$1073,($C$2:$C$1073=$C9)*($E$2:$E$1073=$E9)*(ROW(S$2:S$1073)<>ROW(S9))*(S$2:S$1073<>""))),"")} -> 0.75475667 | Z9: {=IFERROR(AVERAGE(_xlfn._xlws.FILTER(T$2:T$1073,($C$2:$C$1073=$C9)*($E$2:$E$1073=$E9)*(ROW(T$2:T$1073)<>ROW(T9))*(T$2:T$1073<>""))),"")} -> 0.12546632 | AA9: {=IFERROR(AVERAGE(_xlfn._xlws.FILTER(U$2:U$1073,($C$2:$C$1073=$C9)*($E$2:$E$1073=$E9)*(ROW(U$2:U$1073)<>ROW(U9))*(U$2:U$1073<>""))),"")} -> 0.92459536
A10: GAZP | B10: =A10&" "& "IV" &" кв. "&C10 -> GAZP IV кв. 2017 | C10: 2017 | D10: =SUMIFS(Дивиденды!$C:$C,Дивиденды!$A:$A,A10,Дивиденды!$I:$I,C10) -> 8.04 | E10: 1 | F10: =D10 -> 8.04 | G10: =AVERAGEIFS($D:$D,$E:$E,E10,$C:$C,C10,$A:$A,"<>"&A10) -> 46.836667 | H10: =IF(D10>0,1,0) -> 1 | I10: =IFERROR((COUNTIFS($E:$E,E10,$C:$C,C10,$H:$H,1)-H10)/(COUNTIFS($E:$E,E10,$C:$C,C10)-1),0) -> 0.83333333 | J10: =IF(A11<>A10,"",IF(D10=D11,0,IF(AND(D11=0,D10<>0), 1,(D10-D11)/D11))) -> 0 | K10: =IFERROR(AVERAGEIFS($J:$J,$E:$E,E10,$C:$C,C10,$A:$A,"<>"&A10),"") -> 0.2941553 | L10: =IF(J10<>"",IF(J10>0,1,0),"") -> 0 | M10: =IFERROR(AVERAGEIFS($L:$L,$E:$E,E10,$C:$C,C10,$A:$A,"<>"&A10),"") -> 0.83333333 | N10: =IF(J10<>"",IF(J10<0,1,0),"") -> 0 | O10: =IFERROR(AVERAGEIFS($N:$N,$E:$E,E10,$C:$C,C10,$A:$A,"<>"&A10),"") -> 0 | P10: =IFERROR(LN('Дивиденды по годам'!I10),"") -> 30.534571 | Q10: =IFERROR('Дивиденды по годам'!G10/'Дивиденды по годам'!I10, "") -> 0.68782484 | R10: =IFERROR(IF(AND('Дивиденды по годам'!N10<>"",'Дивиденды по годам'!U10<>"",'Дивиденды по годам'!U10<>0),'Дивиденды по годам'!N10/'Дивиденды по годам'!U10-1,""),"") -> 0.071197573 | S10: =IFERROR(IF(AND('Дивиденды по годам'!L10<>"",'Дивиденды по годам'!I10<>"",'Дивиденды по годам'!J10<>"",'Дивиденды по годам'!K10<>"",('Дивиденды по годам'!I10-'Дивиденды по годам'!J10-'Дивиденды по годам'!K10)<>0),'Дивиденды по годам'!L10/('Дивиденды по годам'!I10-'Дивиденды по годам'!J10-'Дивиденды по годам'!K10),""),"") -> 0.96041191 | T10: =IFERROR(IF(AND('Дивиденды по годам'!Q10<>"",'Дивиденды по годам'!I10<>"",'Дивиденды по годам'!V10<>"",('Дивиденды по годам'!I10+'Дивиденды по годам'!V10)<>0),'Дивиденды по годам'!Q10/(('Дивиденды по годам'!I10+'Дивиденды по годам'!V10)/2),""),"") -> 0.043625085 | U10: =IFERROR(IF(AND('Дивиденды по годам'!J10<>"",'Дивиденды по годам'!K10<>"",'Дивиденды по годам'!M10<>"",'Дивиденды по годам'!M10<>0),('Дивиденды по годам'!J10+'Дивиденды по годам'!K10)/'Дивиденды по годам'!M10,""),"") -> 0.51793923 | V10: {=IFERROR(AVERAGE(_xlfn._xlws.FILTER(P$2:P$1073,($C$2:$C$1073=$C10)*($E$2:$E$1073=$E10)*(ROW(P$2:P$1073)<>ROW(P10))*(P$2:P$1073<>""))),"")} -> 28.340294 | W10: {=IFERROR(AVERAGE(_xlfn._xlws.FILTER(Q$2:Q$1073,($C$2:$C$1073=$C10)*($E$2:$E$1073=$E10)*(ROW(Q$2:Q$1073)<>ROW(Q10))*(Q$2:Q$1073<>""))),"")} -> 0.5242558 | X10: {=IFERROR(AVERAGE(_xlfn._xlws.FILTER(R$2:R$1073,($C$2:$C$1073=$C10)*($E$2:$E$1073=$E10)*(ROW(R$2:R$1073)<>ROW(R10))*(R$2:R$1073<>""))),"")} -> 0.16368052 | Y10: {=IFERROR(AVERAGE(_xlfn._xlws.FILTER(S$2:S$1073,($C$2:$C$1073=$C10)*($E$2:$E$1073=$E10)*(ROW(S$2:S$1073)<>ROW(S10))*(S$2:S$1073<>""))),"")} -> 0.73280408 | Z10: {=IFERROR(AVERAGE(_xlfn._xlws.FILTER(T$2:T$1073,($C$2:$C$1073=$C10)*($E$2:$E$1073=$E10)*(ROW(T$2:T$1073)<>ROW(T10))*(T$2:T$1073<>""))),"")} -> 0.077823093 | AA10: {=IFERROR(AVERAGE(_xlfn._xlws.FILTER(U$2:U$1073,($C$2:$C$1073=$C10)*($E$2:$E$1073=$E10)*(ROW(U$2:U$1073)<>ROW(U10))*(U$2:U$1073<>""))),"")} -> 0.97472196
A11: GAZP | B11: =A11&" "& "IV" &" кв. "&C11 -> GAZP IV кв. 2016 | C11: 2016 | D11: =SUMIFS(Дивиденды!$C:$C,Дивиденды!$A:$A,A11,Дивиденды!$I:$I,C11) -> 8.04 | E11: 1 | F11: =D11 -> 8.04 | G11: =AVERAGEIFS($D:$D,$E:$E,E11,$C:$C,C11,$A:$A,"<>"&A11) -> 39.715 | H11: =IF(D11>0,1,0) -> 1 | I11: =IFERROR((COUNTIFS($E:$E,E11,$C:$C,C11,$H:$H,1)-H11)/(COUNTIFS($E:$E,E11,$C:$C,C11)-1),0) -> 0.83333333 | J11: =IF(A12<>A11,"",IF(D11=D12,0,IF(AND(D12=0,D11<>0), 1,(D11-D12)/D12))) -> 0.019011407 | K11: =IFERROR(AVERAGEIFS($J:$J,$E:$E,E11,$C:$C,C11,$A:$A,"<>"&A11),"") -> 0.12024418 | L11: =IF(J11<>"",IF(J11>0,1,0),"") -> 1 | M11: =IFERROR(AVERAGEIFS($L:$L,$E:$E,E11,$C:$C,C11,$A:$A,"<>"&A11),"") -> 0.5 | N11: =IF(J11<>"",IF(J11<0,1,0),"") -> 0 | O11: =IFERROR(AVERAGEIFS($N:$N,$E:$E,E11,$C:$C,C11,$A:$A,"<>"&A11),"") -> 0.16666667 | P11: =IFERROR(LN('Дивиденды по годам'!I11),"") -> 30.459455 | Q11: =IFERROR('Дивиденды по годам'!G11/'Дивиденды по годам'!I11, "") -> 0.67987406 | R11: =IFERROR(IF(AND('Дивиденды по годам'!N11<>"",'Дивиденды по годам'!U11<>"",'Дивиденды по годам'!U11<>0),'Дивиденды по годам'!N11/'Дивиденды по годам'!U11-1,""),"") -> 0.0062129136 | S11: =IFERROR(IF(AND('Дивиденды по годам'!L11<>"",'Дивиденды по годам'!I11<>"",'Дивиденды по годам'!J11<>"",'Дивиденды по годам'!K11<>"",('Дивиденды по годам'!I11-'Дивиденды по годам'!J11-'Дивиденды по годам'!K11)<>0),'Дивиденды по годам'!L11/('Дивиденды по годам'!I11-'Дивиденды по годам'!J11-'Дивиденды по годам'!K11),""),"") -> 0.96184328 | T11: =IFERROR(IF(AND('Дивиденды по годам'!Q11<>"",'Дивиденды по годам'!I11<>"",'Дивиденды по годам'!V11<>"",('Дивиденды по годам'!I11+'Дивиденды по годам'!V11)<>0),'Дивиденды по годам'!Q11/(('Дивиденды по годам'!I11+'Дивиденды по годам'!V11)/2),""),"") -> 0.058703285 | U11: =IFERROR(IF(AND('Дивиденды по годам'!J11<>"",'Дивиденды по годам'!K11<>"",'Дивиденды по годам'!M11<>"",'Дивиденды по годам'!M11<>0),('Дивиденды по годам'!J11+'Дивиденды по годам'!K11)/'Дивиденды по годам'!M11,""),"") -> 0.47869044 | V11: {=IFERROR(AVERAGE(_xlfn._xlws.FILTER(P$2:P$1073,($C$2:$C$1073=$C11)*($E$2:$E$1073=$E11)*(ROW(P$2:P$1073)<>ROW(P11))*(P$2:P$1073<>""))),"")} -> 28.279917 | W11: {=IFERROR(AVERAGE(_xlfn._xlws.FILTER(Q$2:Q$1073,($C$2:$C$1073=$C11)*($E$2:$E$1073=$E11)*(ROW(Q$2:Q$1073)<>ROW(Q11))*(Q$2:Q$1073<>""))),"")} -> 0.50976916 | X11: {=IFERROR(AVERAGE(_xlfn._xlws.FILTER(R$2:R$1073,($C$2:$C$1073=$C11)*($E$2:$E$1073=$E11)*(ROW(R$2:R$1073)<>ROW(R11))*(R$2:R$1073<>""))),"")} -> 0.012025011 | Y11: {=IFERROR(AVERAGE(_xlfn._xlws.FILTER(S$2:S$1073,($C$2:$C$1073=$C11)*($E$2:$E$1073=$E11)*(ROW(S$2:S$1073)<>ROW(S11))*(S$2:S$1073<>""))),"")} -> 0.68181067 | Z11: {=IFERROR(AVERAGE(_xlfn._xlws.FILTER(T$2:T$1073,($C$2:$C$1073=$C11)*($E$2:$E$1073=$E11)*(ROW(T$2:T$1073)<>ROW(T11))*(T$2:T$1073<>""))),"")} -> 0.10464156 | AA11: {=IFERROR(AVERAGE(_xlfn._xlws.FILTER(U$2:U$1073,($C$2:$C$1073=$C11)*($E$2:$E$1073=$E11)*(ROW(U$2:U$1073)<>ROW(U11))*(U$2:U$1073<>""))),"")} -> 1.0228333
A12: GAZP | B12: =A12&" "& "IV" &" кв. "&C12 -> GAZP IV кв. 2015 | C12: 2015 | D12: =SUMIFS(Дивиденды!$C:$C,Дивиденды!$A:$A,A12,Дивиденды!$I:$I,C12) -> 7.89 | E12: 1 | F12: =D12 -> 7.89 | G12: =AVERAGEIFS($D:$D,$E:$E,E12,$C:$C,C12,$A:$A,"<>"&A12) -> 35.635 | H12: =IF(D12>0,1,0) -> 1 | I12: =IFERROR((COUNTIFS($E:$E,E12,$C:$C,C12,$H:$H,1)-H12)/(COUNTIFS($E:$E,E12,$C:$C,C12)-1),0) -> 0.83333333 | J12: =IF(A13<>A12,"",IF(D12=D13,0,IF(AND(D13=0,D12<>0), 1,(D12-D13)/D13))) -> 0.095833333 | K12: =IFERROR(AVERAGEIFS($J:$J,$E:$E,E12,$C:$C,C12,$A:$A,"<>"&A12),"") -> 0.14170092 | L12: =IF(J12<>"",IF(J12>0,1,0),"") -> 1 | M12: =IFERROR(AVERAGEIFS($L:$L,$E:$E,E12,$C:$C,C12,$A:$A,"<>"&A12),"") -> 0.66666667 | N12: =IF(J12<>"",IF(J12<0,1,0),"") -> 0 | O12: =IFERROR(AVERAGEIFS($N:$N,$E:$E,E12,$C:$C,C12,$A:$A,"<>"&A12),"") -> 0.16666667 | P12: =IFERROR(LN('Дивиденды по годам'!I12),"") -> 30.467291 | Q12: =IFERROR('Дивиденды по годам'!G12/'Дивиденды по годам'!I12, "") -> 0.6453117 | R12: =IFERROR(IF(AND('Дивиденды по годам'!N12<>"",'Дивиденды по годам'!U12<>"",'Дивиденды по годам'!U12<>0),'Дивиденды по годам'!N12/'Дивиденды по годам'!U12-1,""),"") -> 0.086497916 | S12: =IFERROR(IF(AND('Дивиденды по годам'!L12<>"",'Дивиденды по годам'!I12<>"",'Дивиденды по годам'!J12<>"",'Дивиденды по годам'!K12<>"",('Дивиденды по годам'!I12-'Дивиденды по годам'!J12-'Дивиденды по годам'!K12)<>0),'Дивиденды по годам'!L12/('Дивиденды по годам'!I12-'Дивиденды по годам'!J12-'Дивиденды по годам'!K12),""),"") -> 0.94994687 | T12: =IFERROR(IF(AND('Дивиденды по годам'!Q12<>"",'Дивиденды по годам'!I12<>"",'Дивиденды по годам'!V12<>"",('Дивиденды по годам'!I12+'Дивиденды по годам'!V12)<>0),'Дивиденды по годам'!Q12/(('Дивиденды по годам'!I12+'Дивиденды по годам'!V12)/2),""),"") -> 0.049966568 | U12: =IFERROR(IF(AND('Дивиденды по годам'!J12<>"",'Дивиденды по годам'!K12<>"",'Дивиденды по годам'!M12<>"",'Дивиденды по годам'!M12<>0),('Дивиденды по годам'!J12+'Дивиденды по годам'!K12)/'Дивиденды по годам'!M12,""),"") -> 0.56231155 | V12: {=IFERROR(AVERAGE(_xlfn._xlws.FILTER(P$2:P$1073,($C$2:$C$1073=$C12)*($E$2:$E$1073=$E12)*(ROW(P$2:P$1073)<>ROW(P12))*(P$2:P$1073<>""))),"")} -> 28.027872 | W12: {=IFERROR(AVERAGE(_xlfn._xlws.FILTER(Q$2:Q$1073,($C$2:$C$1073=$C12)*($E$2:$E$1073=$E12)*(ROW(Q$2:Q$1073)<>ROW(Q12))*(Q$2:Q$1073<>""))),"")} -> 0.5715191 | X12: {=IFERROR(AVERAGE(_xlfn._xlws.FILTER(R$2:R$1073,($C$2:$C$1073=$C12)*($E$2:$E$1073=$E12)*(ROW(R$2:R$1073)<>ROW(R12))*(R$2:R$1073<>""))),"")} -> 0.11349517 | Y12: {=IFERROR(AVERAGE(_xlfn._xlws.FILTER(S$2:S$1073,($C$2:$C$1073=$C12)*($E$2:$E$1073=$E12)*(ROW(S$2:S$1073)<>ROW(S12))*(S$2:S$1073<>""))),"")} -> 0.93141876 | Z12: {=IFERROR(AVERAGE(_xlfn._xlws.FILTER(T$2:T$1073,($C$2:$C$1073=$C12)*($E$2:$E$1073=$E12)*(ROW(T$2:T$1073)<>ROW(T12))*(T$2:T$1073<>""))),"")} -> 0.083332631 | AA12: {=IFERROR(AVERAGE(_xlfn._xlws.FILTER(U$2:U$1073,($C$2:$C$1073=$C12)*($E$2:$E$1073=$E12)*(ROW(U$2:U$1073)<>ROW(U12))*(U$2:U$1073<>""))),"")} -> -1.2671068
A13: GAZP | B13: =A13&" "& "IV" &" кв. "&C13 -> GAZP IV кв. 2014 | C13: 2014 | D13: =SUMIFS(Дивиденды!$C:$C,Дивиденды!$A:$A,A13,Дивиденды!$I:$I,C13) -> 7.2 | E13: 1 | F13: =D13 -> 7.2 | G13: =AVERAGEIFS($D:$D,$E:$E,E13,$C:$C,C13,$A:$A,"<>"&A13) -> 30.623333 | H13: =IF(D13>0,1,0) -> 1 | I13: =IFERROR((COUNTIFS($E:$E,E13,$C:$C,C13,$H:$H,1)-H13)/(COUNTIFS($E:$E,E13,$C:$C,C13)-1),0) -> 0.83333333 | J13: =IF(A14<>A13,"",IF(D13=D14,0,IF(AND(D14=0,D13<>0), 1,(D13-D14)/D14))) -> 0 | K13: =IFERROR(AVERAGEIFS($J:$J,$E:$E,E13,$C:$C,C13,$A:$A,"<>"&A13),"") -> 0.11887241 | L13: =IF(J13<>"",IF(J13>0,1,0),"") -> 0 | M13: =IFERROR(AVERAGEIFS($L:$L,$E:$E,E13,$C:$C,C13,$A:$A,"<>"&A13),"") -> 0.66666667 | N13: =IF(J13<>"",IF(J13<0,1,0),"") -> 0 | O13: =IFERROR(AVERAGEIFS($N:$N,$E:$E,E13,$C:$C,C13,$A:$A,"<>"&A13),"") -> 0.16666667 | P13: =IFERROR(LN('Дивиденды по годам'!I13),"") -> 30.350833 | Q13: =IFERROR('Дивиденды по годам'!G13/'Дивиденды по годам'!I13, "") -> 0.65559075 | R13: =IFERROR(IF(AND('Дивиденды по годам'!N13<>"",'Дивиденды по годам'!U13<>"",'Дивиденды по годам'!U13<>0),'Дивиденды по годам'!N13/'Дивиденды по годам'!U13-1,""),"") -> 0.064733003 | S13: =IFERROR(IF(AND('Дивиденды по годам'!L13<>"",'Дивиденды по годам'!I13<>"",'Дивиденды по годам'!J13<>"",'Дивиденды по годам'!K13<>"",('Дивиденды по годам'!I13-'Дивиденды по годам'!J13-'Дивиденды по годам'!K13)<>0),'Дивиденды по годам'!L13/('Дивиденды по годам'!I13-'Дивиденды по годам'!J13-'Дивиденды по годам'!K13),""),"") -> 0.94814853 | T13: =IFERROR(IF(AND('Дивиденды по годам'!Q13<>"",'Дивиденды по годам'!I13<>"",'Дивиденды по годам'!V13<>"",('Дивиденды по годам'!I13+'Дивиденды по годам'!V13)<>0),'Дивиденды по годам'!Q13/(('Дивиденды по годам'!I13+'Дивиденды по годам'!V13)/2),""),"") -> 0.010987182 | U13: =IFERROR(IF(AND('Дивиденды по годам'!J13<>"",'Дивиденды по годам'!K13<>"",'Дивиденды по годам'!M13<>"",'Дивиденды по годам'!M13<>0),('Дивиденды по годам'!J13+'Дивиденды по годам'!K13)/'Дивиденды по годам'!M13,""),"") -> 0.49974689 | V13: {=IFERROR(AVERAGE(_xlfn._xlws.FILTER(P$2:P$1073,($C$2:$C$1073=$C13)*($E$2:$E$1073=$E13)*(ROW(P$2:P$1073)<>ROW(P13))*(P$2:P$1073<>""))),"")} -> 28.372329 | W13: {=IFERROR(AVERAGE(_xlfn._xlws.FILTER(Q$2:Q$1073,($C$2:$C$1073=$C13)*($E$2:$E$1073=$E13)*(ROW(Q$2:Q$1073)<>ROW(Q13))*(Q$2:Q$1073<>""))),"")} -> 0.62176756 | X13: {=IFERROR(AVERAGE(_xlfn._xlws.FILTER(R$2:R$1073,($C$2:$C$1073=$C13)*($E$2:$E$1073=$E13)*(ROW(R$2:R$1073)<>ROW(R13))*(R$2:R$1073<>""))),"")} -> 0.16466401 | Y13: {=IFERROR(AVERAGE(_xlfn._xlws.FILTER(S$2:S$1073,($C$2:$C$1073=$C13)*($E$2:$E$1073=$E13)*(ROW(S$2:S$1073)<>ROW(S13))*(S$2:S$1073<>""))),"")} -> 0.93308346 | Z13: {=IFERROR(AVERAGE(_xlfn._xlws.FILTER(T$2:T$1073,($C$2:$C$1073=$C13)*($E$2:$E$1073=$E13)*(ROW(T$2:T$1073)<>ROW(T13))*(T$2:T$1073<>""))),"")} -> 0.071375294 | AA13: {=IFERROR(AVERAGE(_xlfn._xlws.FILTER(U$2:U$1073,($C$2:$C$1073=$C13)*($E$2:$E$1073=$E13)*(ROW(U$2:U$1073)<>ROW(U13))*(U$2:U$1073<>""))),"")} -> 0.86783657
... A1073: SMLT | B1073: =A1073&" "& "IV" &" кв. "&C1073 -> SMLT IV кв. 2010 | C1073: 2010 | D1073: =SUMIFS(Дивиденды!$C:$C,Дивиденды!$A:$A,A1073,Дивиденды!$I:$I,C1073) -> 0 | E1073: 8 | F1073: =D1073 -> 0 | G1073: =AVERAGEIFS($D:$D,$E:$E,E1073,$C:$C,C1073,$A:$A,"<>"&A1073) -> 5 | H1073: =IF(D1073>0,1,0) -> 0 | I1073: =IFERROR((COUNTIFS($E:$E,E1073,$C:$C,C1073,$H:$H,1)-H1073)/(COUNTIFS($E:$E,E1073,$C:$C,C1073)-1),0) -> 0.33333333 | J1073: =IF(A1074<>A1073,"",IF(D1073=D1074,0,IF(AND(D1074=0,D1073<>0), 1,(D1073-D1074)/D1074))) | K1073: =IFERROR(AVERAGEIFS($J:$J,$E:$E,E1073,$C:$C,C1073,$A:$A,"<>"&A1073),"") | L1073: =IF(J1073<>"",IF(J1073>0,1,0),"") | M1073: =IFERROR(AVERAGEIFS($L:$L,$E:$E,E1073,$C:$C,C1073,$A:$A,"<>"&A1073),"") | N1073: =IF(J1073<>"",IF(J1073<0,1,0),"") | O1073: =IFERROR(AVERAGEIFS($N:$N,$E:$E,E1073,$C:$C,C1073,$A:$A,"<>"&A1073),"") | P1073: =IFERROR(LN('Дивиденды по годам'!I1073),"") | Q1073: =IFERROR('Дивиденды по годам'!G1073/'Дивиденды по годам'!I1073, "") | R1073: =IFERROR(IF(AND('Дивиденды по годам'!N1073<>"",'Дивиденды по годам'!U1073<>"",'Дивиденды по годам'!U1073<>0),'Дивиденды по годам'!N1073/'Дивиденды по годам'!U1073-1,""),"") | S1073: =IFERROR(IF(AND('Дивиденды по годам'!L1073<>"",'Дивиденды по годам'!I1073<>"",'Дивиденды по годам'!J1073<>"",'Дивиденды по годам'!K1073<>"",('Дивиденды по годам'!I1073-'Дивиденды по годам'!J1073-'Дивиденды по годам'!K1073)<>0),'Дивиденды по годам'!L1073/('Дивиденды по годам'!I1073-'Дивиденды по годам'!J1073-'Дивиденды по годам'!K1073),""),"") | T1073: =IFERROR(IF(AND('Дивиденды по годам'!Q1073<>"",'Дивиденды по годам'!I1073<>"",'Дивиденды по годам'!V1073<>"",('Дивиденды по годам'!I1073+'Дивиденды по годам'!V1073)<>0),'Дивиденды по годам'!Q1073/(('Дивиденды по годам'!I1073+'Дивиденды по годам'!V1073)/2),""),"") | U1073: =IFERROR(IF(AND('Дивиденды по годам'!J1073<>"",'Дивиденды по годам'!K1073<>"",'Дивиденды по годам'!M1073<>"",'Дивиденды по годам'!M1073<>0),('Дивиденды по годам'!J1073+'Дивиденды по годам'!K1073)/'Дивиденды по годам'!M1073,""),"") | V1073: {=IFERROR(AVERAGE(_xlfn._xlws.FILTER(P$2:P$1073,($C$2:$C$1073=$C1073)*($E$2:$E$1073=$E1073)*(ROW(P$2:P$1073)<>ROW(P1073))*(P$2:P$1073<>""))),"")} | W1073: {=IFERROR(AVERAGE(_xlfn._xlws.FILTER(Q$2:Q$1073,($C$2:$C$1073=$C1073)*($E$2:$E$1073=$E1073)*(ROW(Q$2:Q$1073)<>ROW(Q1073))*(Q$2:Q$1073<>""))),"")} | X1073: {=IFERROR(AVERAGE(_xlfn._xlws.FILTER(R$2:R$1073,($C$2:$C$1073=$C1073)*($E$2:$E$1073=$E1073)*(ROW(R$2:R$1073)<>ROW(R1073))*(R$2:R$1073<>""))),"")} | Y1073: {=IFERROR(AVERAGE(_xlfn._xlws.FILTER(S$2:S$1073,($C$2:$C$1073=$C1073)*($E$2:$E$1073=$E1073)*(ROW(S$2:S$1073)<>ROW(S1073))*(S$2:S$1073<>""))),"")} | Z1073: {=IFERROR(AVERAGE(_xlfn._xlws.FILTER(T$2:T$1073,($C$2:$C$1073=$C1073)*($E$2:$E$1073=$E1073)*(ROW(T$2:T$1073)<>ROW(T1073))*(T$2:T$1073<>""))),"")} | AA1073: {=IFERROR(AVERAGE(_xlfn._xlws.FILTER(U$2:U$1073,($C$2:$C$1073=$C1073)*($E$2:$E$1073=$E1073)*(ROW(U$2:U$1073)<>ROW(U1073))*(U$2:U$1073<>""))),"")}

Sheet Sheet2
A1: company | B1: Наименование | C1: year | D1: Дивиденд | E1: industry | F1: sum | G1: peer_sum | H1: payout | I1: payout_ratio | J1: abs | K1: pabs | L1: inc | M1: inc_ratio | N1: dec | O1: dec_ratio | P1: Size | Q1: Tangibility | R1: Sales_growth | S1: REBE | T1: ROA | U1: Leverage | V1: Psize | W1: PTangibility | X1: PSales_growth | Y1: PREBE | Z1: PROA | AA1: PLeverage
A2: GAZP | B2: GAZP IV кв. 2024 | C2: 2024 | D2: 0 | E2: 1 | F2: 0 | G2: 214.65 | H2: 0 | I2: 0.83333333 | J2: 0 | K2: 0.033213968 | L2: 0 | M2: 0.66666667 | N2: 0 | O2: 0.16666667 | P2: 31.055227 | Q2: 0.67690981 | R2: 0.25438004 | S2: 0.88491057 | T2: 0.04439204 | U2: 0.73819835 | V2: 28.89571 | W2: 0.51199198 | X2: 0.17118061 | Y2: 0.79852548 | Z2: 0.12177692 | AA2: 0.85190113
A3: GAZP | B3: GAZP IV кв. 2023 | C3: 2023 | D3: 0 | E3: 1 | F3: 0 | G3: 195.35 | H3: 0 | I3: 0.83333333 | J3: -1 | K3: 0.07318505 | L3: 0 | M3: 0.5 | N3: 1 | O3: 0.33333333 | P3: 30.988397 | Q3: 0.64206898 | R3: -0.26830096 | S3: 0.88690206 | T3: -0.021263586 | U3: 0.74522866 | V3: 28.950488 | W3: 0.47348976 | X3: -0.037500665 | Y3: 0.80302193 | Z3: 0.11841775 | AA3: 0.83818778
A4: GAZP | B4: GAZP IV кв. 2022 | C4: 2022 | D4: 51.03 | E4: 1 | F4: 51.03 | G4: 240.50333 | H4: 1 | I4: 0.83333333 | J4: 1 | K4: 0.59952004 | L4: 1 | M4: 0.5 | N4: 0 | O4: 0.16666667 | P4: 30.894064 | Q4: 0.66665802 | R4: 0.13988357 | S4: 0.9197466 | T4: 0.04933207 | U4: 0.58878604 | V4: 28.005023 | W4: 0.45949876 | X4: 0.1038114 | Y4: 0.78172804 | Z4: 0.12952165 | AA4: 0.8837483
A5: GAZP | B5: GAZP IV кв. 2021 | C5: 2021 | D5: 0 | E5: 1 | F5: 0 | G5: 82.756667 | H5: 0 | I5: 0.83333333 | J5: -1 | K5: 1.2307909 | L5: 0 | M5: 0.83333333 | N5: 1 | O5: 0 | P5: 30.928606 | Q5: 0.61646121 | R5: 0.62006761 | S5: 0.92570438 | T5: 0.08567901 | U5: 0.60359905 | V5: 28.588015 | W5: 0.54592305 | X5: 0.71962064 | Y5: 0.78164523 | Z5: 0.12893486 | AA5: 1.1281548
A6: GAZP | B6: GAZP IV кв. 2020 | C6: 2020 | D6: 12.55 | E6: 1 | F6: 12.55 | G6: 54.073333 | H6: 1 | I6: 0.83333333 | J6: -0.17650919 | K6: -0.29877017 | L6: 0 | M6: 0.33333333 | N6: 1 | O6: 0.5 | P6: 30.781712 | Q6: 0.68957552 | R6: -0.17469058 | S6: 0.92655943 | T6: 0.0071806644 | U6: 0.57734601 | V6: 28.624109 | W6: 0.5371219 | X6: -0.27049471 | Y6: 0.74822584 | Z6: 0.032136749 | AA6: 1.2967729
A7: GAZP | B7: GAZP IV кв. 2019 | C7: 2019 | D7: 15.24 | E7: 1 | F7: 15.24 | G7: 112.14333 | H7: 1 | I7: 0.83333333 | J7: -0.082480433 | K7: 0.24288945 | L7: 0 | M7: 0.5 | N7: 1 | O7: 0.16666667 | P7: 30.716701 | Q7: 0.67892385 | R7: -0.068645653 | S7: 0.94282055 | T7: 0.059472199 | U7: 0.49718231 | V7: 28.572217 | W7: 0.51462951 | X7: 0.025367391 | Y7: 0.82043004 | Z7: 0.16320282 | AA7: 0.95146752
A8: GAZP | B8: GAZP IV кв. 2018 | C8: 2018 | D8: 16.61 | E8: 1 | F8: 16.61 | G8: 64.588333 | H8: 1 | I8: 0.83333333 | J8: 1.0659204 | K8: 0.58403361 | L8: 1 | M8: 0.66666667 | N8: 0 | O8: 0 | P8: 30.666476 | Q8: 0.66358203 | R8: 0.25633934 | S8: 0.95895668 | T8: 0.078311239 | U8: 0.5106133 | V8: 28.458498 | W8: 0.50857093 | X8: 0.36447021 | Y8: 0.75475667 | Z8: 0.12546632 | AA8: 0.92459536
A9: GAZP | B9: GAZP IV кв. 2017 | C9: 2017 | D9: 8.04 | E9: 1 | F9: 8.04 | G9: 46.836667 | H9: 1 | I9: 0.83333333 | J9: 0 | K9: 0.2941553 | L9: 0 | M9: 0.83333333 | N9: 0 | O9: 0 | P9: 30.534571 | Q9: 0.68782484 | R9: 0.071197573 | S9: 0.96041191 | T9: 0.043625085 | U9: 0.51793923 | V9: 28.340294 | W9: 0.5242558 | X9: 0.16368052 | Y9: 0.73280408 | Z9: 0.077823093 | AA9: 0.97472196
A10: GAZP | B10: GAZP IV кв. 2016 | C10: 2016 | D10: 8.04 | E10: 1 | F10: 8.04 | G10: 39.715 | H10: 1 | I10: 0.83333333 | J10: 0.019011407 | K10: 0.12024418 | L10: 1 | M10: 0.5 | N10: 0 | O10: 0.16666667 | P10: 30.459455 | Q10: 0.67987406 | R10: 0.0062129136 | S10: 0.96184328 | T10: 0.058703285 | U10: 0.47869044 | V10: 28.279917 | W10: 0.50976916 | X10: 0.012025011 | Y10: 0.68181067 | Z10: 0.10464156 | AA10: 1.0228333
A11: GAZP | B11: GAZP IV кв. 2015 | C11: 2015 | D11: 7.89 | E11: 1 | F11: 7.89 | G11: 35.635 | H11: 1 | I11: 0.83333333 | J11: 0.095833333 | K11: 0.14170092 | L11: 1 | M11: 0.66666667 | N11: 0 | O11: 0.16666667 | P11: 30.467291 | Q11: 0.6453117 | R11: 0.086497916 | S11: 0.94994687 | T11: 0.049966568 | U11: 0.56231155 | V11: 28.027872 | W11: 0.5715191 | X11: 0.11349517 | Y11: 0.93141876 | Z11: 0.083332631 | AA11: -1.2671068
A12: GAZP | B12: GAZP IV кв. 2014 | C12: 2014 | D12: 7.2 | E12: 1 | F12: 7.2 | G12: 30.623333 | H12: 1 | I12: 0.83333333 | J12: 0 | K12: 0.11887241 | L12: 0 | M12: 0.66666667 | N12: 0 | O12: 0.16666667 | P12: 30.350833 | Q12: 0.65559075 | R12: 0.064733003 | S12: 0.94814853 | T12: 0.010987182 | U12: 0.49974689 | V12: 28.372329 | W12: 0.62176756 | X12: 0.16466401 | Y12: 0.98195602 | Z12: 0.071375294 | AA12: 0.86783657
A13: GAZP | B13: GAZP IV кв. 2012 | C13: 2012 | D13: 5.99 | E13: 1 | F13: 5.99 | G13: 19.001667 | H13: 1 | I13: 0.83333333 | J13: -0.33221851 | K13: 0.076735506 | L13: 0 | M13: 0.66666667 | N13: 1 | O13: 0.16666667 | P13: 30.12159 | Q13: 0.64785399 | R13: 0.027457091 | S13: 0.93903491 | T13: 0.10540944 | U13: 0.38696801 | V13: 27.941602 | W13: 0.6129454 | X13: 0.039420032 | Z13: 0.12618572 | AA13: 0.50988452
A14: LKOH | B14: LKOH IV кв. 2025 | C14: 2025 | D14: 397 | E14: 1 | F14: 397 | G14: 11.59 | H14: 1 | I14: 0.5 | J14: -0.62369668 | K14: -0.5190168 | L14: 0 | M14: 0 | N14: 1 | O14: 0.66666667 | P14: 29.331108 | Q14: 0.68588587 | R14: -0.56298308 | S14: 1.1230089 | T14: -0.14364114 | U14: 0.50958002 | V14: 28.648938 | W14: 0.47597261 | X14: -0.084693664 | Y14: 0.92840826 | Z14: 0.060424107 | AA14: 0.43679759
A15: LKOH | B15: LKOH IV кв. 2024 | C15: 2024 | D15: 1055 | E15: 1 | F15: 1055 | G15: 38.816667 | H15: 1 | I15: 0.66666667 | J15: 0.11640212 | K15: 0.013813615 | L15: 1 | M15: 0.5 | N15: 0 | O15: 0.16666667 | P15: 29.859165 | Q15: 0.54042765 | R15: 0.087440906 | S15: 0.82896494 | T15: 0.095236359 | U15: 0.34686712 | V15: 29.134922 | W15: 0.53928841 | X15: 0.20456844 | Y15: 0.81251189 | Z15: 0.11160806 | AA15: 0.93016738
A16: LKOH | B16: LKOH IV кв. 2021 | C16: 2021 | D16: 340 | E16: 1 | F16: 340 | G16: 26.09 | H16: 1 | I16: 0.66666667 | J16: 0.31274131 | K16: 1.0120007 | L16: 1 | M16: 0.66666667 | N16: 0 | O16: 0.16666667 | P16: 29.557421 | Q16: 0.62101761 | R16: 0.67307539 | S16: 0.94628607 | T16: 0.120643 | U16: 0.51768069 | V16: 28.862252 | W16: 0.54501177 | X16: 0.70901908 | Y16: 0.77752889 | Z16: 0.12194206 | AA16: 1.1453385
A17: LKOH | B17: LKOH IV кв. 2020 | C17: 2020 | D17: 259 | E17: 1 | F17: 259 | G17: 12.998333 | H17: 1 | I17: 0.83333333 | J17: -0.52214022 | K17: -0.241165 | L17: 0 | M17: 0.33333333 | N17: 1 | O17: 0.5 | P17: 29.421376 | Q17: 0.7117446 | R17: -0.28080295 | S17: 0.93398101 | T17: 0.0027864171 | U17: 0.4504765 | V17: 28.850832 | W17: 0.53342706 | X17: -0.25280932 | Y17: 0.74698891 | Z17: 0.032869124 | AA17: 1.3179179
A18: LKOH | B18: LKOH IV кв. 2019 | C18: 2019 | D18: 542 | E18: 1 | F18: 542 | G18: 24.35 | H18: 1 | I18: 0.83333333 | J18: 1.168 | K18: 0.03447604 | L18: 1 | M18: 0.33333333 | N18: 0 | O18: 0.33333333 | P18: 29.413916 | Q18: 0.67697548 | R18: -0.024221713 | S18: 1.057806 | T18: 0.1099747 | U18: 0.4966972 | V18: 28.789348 | W18: 0.51495424 | X18: 0.017963401 | Y18: 0.80126581 | Z18: 0.15478573 | AA18: 0.95154837
A19: LKOH | B19: LKOH IV кв. 2018 | C19: 2018 | D19: 250 | E19: 1 | F19: 250 | G19: 25.69 | H19: 1 | I19: 0.83333333 | J19: 0.1627907 | K19: 0.73455523 | L19: 1 | M19: 0.66666667 | N19: 0 | O19: 0 | P19: 29.377152 | Q19: 0.66798828 | R19: 0.35359412 | S19: 0.97302141 | T19: 0.11335429 | U19: 0.40722853 | V19: 28.673386 | W19: 0.50783656 | X19: 0.34826108 | Y19: 0.75241255 | Z19: 0.11962581 | AA19: 0.94182616
A20: LKOH | B20: LKOH IV кв. 2017 | C20: 2017 | D20: 215 | E20: 1 | F20: 215 | G20: 12.343333 | H20: 1 | I20: 0.83333333 | J20: 0.1025641 | K20: 0.27706128 | L20: 1 | M20: 0.66666667 | N20: 0 | O20: 0 | P20: 29.284708 | Q20: 0.68408303 | R20: 0.13576696 | S20: 1.02457 | T20: 0.082106552 | U20: 0.49731163 | V20: 28.548605 | W20: 0.52487944 | X20: 0.15291895 | Y20: 0.72211107 | Z20: 0.071409515 | AA20: 0.97815989
A21: LKOH | B21: LKOH IV кв. 2016 | C21: 2016 | D21: 195 | E21: 1 | F21: 195 | G21: 8.555 | H21: 1 | I21: 0.83333333 | J21: 0.10169492 | K21: 0.1064636 | L21: 1 | M21: 0.5 | N21: 0 | O21: 0.16666667 | P21: 29.243389 | Q21: 0.67628856 | R21: -0.09079848 | S21: 1.0232958 | T21: 0.041382403 | U21: 0.55365397 | V21: 28.482595 | W21: 0.51036674 | X21: 0.03142729 | Y21: 0.66952017 | Z21: 0.10810574 | AA21: 1.0103394
A22: LKOH | B22: LKOH IV кв. 2015 | C22: 2015 | D22: 177 | E22: 1 | F22: 177 | G22: 7.45 | H22: 1 | I22: 0.83333333 | J22: 0.14935065 | K22: 0.13278136 | L22: 1 | M22: 0.66666667 | N22: 0 | O22: 0.16666667 | P22: 29.244572 | Q22: 0.6794304 | R22: 0.028796563 | S22: 0.99938262 | T22: 0.062591509 | U22: 0.55370657 | V22: 28.272415 | W22: 0.56469536 | X22: 0.12792051 | Y22: 0.92153161 | Z22: 0.080176396 | AA22: -1.2653858
A23: LKOH | B23: LKOH IV кв. 2014 | C23: 2014 | D23: 154 | E23: 1 | F23: 154 | G23: 6.1566667 | H23: 1 | I23: 0.83333333 | J23: 0.4 | K23: 0.052205747 | L23: 1 | M23: 0.5 | N23: 0 | O23: 0.16666667 | P23: 29.097405 | Q23: 0.72868515 | R23: 0.23981588 | S23: 1.0364466 | T23: 0.04672791 | U23: 0.37427476 | V23: 28.685686 | W23: 0.60349396 | X23: 0.12089329 | Y23: 0.95252334 | Z23: 0.062440112 | AA23: 0.89920461
A24: NVTK | B24: NVTK IV кв. 2021 | C24: 2021 | D24: 71.44 | E24: 1 | F24: 71.44 | G24: 70.85 | H24: 1 | I24: 0.66666667 | J24: 1.0089989 | K24: 0.89595775 | L24: 1 | M24: 0.66666667 | N24: 0 | O24: 0.16666667 | P24: 28.530232 | Q24: 0.35421482 | R24: 0.62504144 | S24: 0.98415721 | T24: 0.19997202 | U24: 0.2857462 | V24: 29.067689 | W24: 0.59837233 | X24: 0.71862587 | Y24: 0.76995467 | Z24: 0.10607626 | AA24: 1.1917254
A25: NVTK | B25: NVTK IV кв. 2020 | C25: 2020 | D25: 35.56 | E25: 1 | F25: 35.56 | G25: 50.238333 | H25: 1 | I25: 0.83333333 | J25: 0.099907207 | K25: -0.34483957 | L25: 1 | M25: 0.16666667 | N25: 0 | O25: 0.66666667 | P25: 28.353328 | Q25: 0.35422241 | R25: -0.17500055 | S25: 0.97678505 | T25: 0.038597805 | U25: 0.2568018 | V25: 29.02884 | W25: 0.59301409 | X25: -0.27044305 | Y25: 0.7398549 | Z25: 0.026900559 | AA25: 1.350197
... A356: POSI | B356: POSI IV кв. 2021 | C356: 2021 | D356: 0 | E356: 5 | F356: 0 | G356: 0 | H356: 0 | I356: 0 | J356: 0 | K356: 0 | L356: 0 | M356: 0 | N356: 0 | O356: 0 | P356: 22.960963 | Q356: 0.059124874 | R356: 0.27950276 | S356: 0.99063987 | T356: 0.24063218 | U356: 1.6755493 | V356: 22.867511 | W356: 0.03011899 | X356: -0.040523781 | Y356: 0.43827851 | Z356: 0.029047209 | AA356: 17.210609
A357: POSI | B357: POSI IV кв. 2020 | C357: 2020 | D357: 0 | E357: 5 | F357: 0 | G357: 0 | H357: 0 | I357: 0 | J357: 0 | K357: 0 | L357: 0 | M357: 0 | N357: 0 | O357: 0 | P357: 22.60051 | Q357: 0.056237144 | R357: 0.60261811 | S357: 0.98625241 | T357: 0.26070423 | U357: 1.5905917 | V357: 24.198271 | W357: 0.011672549 | Y357: 0.7652293 | AA357: 6.3689254
A358: POSI | B358: POSI IV кв. 2019 | C358: 2019 | D358: 0 | E358: 5 | F358: 0 | G358: 0 | H358: 0 | I358: 0 | J358: 0 | K358: 0 | L358: 0 | M358: 0 | N358: 0 | O358: 0 | P358: 22.346826 | Q358: 0.075056137 | R358: 0.33893564 | S358: 0.96665544 | T358: 0.034488878 | U358: 4.0219461
A359: SOFL | B359: SOFL IV кв. 2024 | C359: 2024 | D359: 0 | E359: 5 | F359: 0 | G359: 120.67778 | H359: 0 | I359: 0.55555556 | J359: 0 | K359: 0.33674983 | L359: 0 | M359: 0.44444444 | N359: 0 | O359: 0.11111111 | P359: 25.317112 | Q359: 0.056273641 | R359: 0.10856643 | S359: 0.50325302 | T359: 0.030036161 | U359: 3.4363979 | V359: 24.578397 | W359: 0.07857655 | X359: 0.33435999 | Y359: 0.22556988 | Z359: 0.28396905 | AA359: 2.575913
A360: SOFL | B360: SOFL IV кв. 2023 | C360: 2023 | D360: 0 | E360: 5 | F360: 0 | G360: 16.477778 | H360: 0 | I360: 0.11111111 | J360: 0 | K360: 0.31688312 | L360: 0 | M360: 0.11111111 | N360: 0 | O360: 0 | P360: 25.034293 | Q360: 0.027510501 | R360: 0.30108808 | S360: 1.1490136 | T360: 0.051605332 | U360: 7.7502349 | V360: 23.889672 | W360: 0.044771405 | X360: 0.5796406 | Y360: 0.60461286 | Z360: 0.24226663 | AA360: 1.1370915
A361: SOFL | B361: SOFL IV кв. 2022 | C361: 2022 | D361: 0 | E361: 5 | F361: 0 | G361: 4.2777778 | H361: 0 | I361: 0.11111111 | J361: 0 | K361: 0.11111111 | L361: 0 | M361: 0.11111111 | N361: 0 | O361: 0 | P361: 24.524871 | Q361: 0.024992741 | R361: -0.1546023 | S361: 0.69300664 | T361: 0.16477792 | U361: 3.5710056 | V361: 24.243774 | W361: 0.067358083 | X361: 1.2227001 | Y361: 0.83534038 | Z361: 0.59897421 | AA361: 1.8103122
A362: SOFL | B362: SOFL IV кв. 2021 | C362: 2021 | D362: 0 | E362: 5 | F362: 0 | G362: 0 | H362: 0 | I362: 0 | J362: 0 | K362: 0 | L362: 0 | M362: 0 | N362: 0 | O362: 0 | P362: 24.247831 | Q362: 0.022393117 | R362: -0.040523781 | S362: 0.18243626 | T362: 0.029047209 | U362: 18.228895 | V362: 22.224077 | W362: 0.048484869 | X362: 0.27950276 | Y362: 0.84238031 | Z362: 0.24063218 | AA362: 8.933936
A363: YDEX | B363: YDEX IV кв. 2025 | C363: 2025 | D363: 80 | E363: 5 | F363: 80 | G363: 54.051111 | H363: 1 | I363: 0.55555556 | J363: -0.5 | K363: 0.24947366 | L363: 0 | M363: 0.44444444 | N363: 1 | O363: 0.33333333 | P363: 27.944621 | Q363: 0.24201917 | R363: 0.31660028 | S363: 0.73713612 | T363: 0.064514011 | U363: 2.8960127 | V363: 25.378142 | W363: 0.094722753 | X363: 0.061966379 | Y363: 0.6499985 | Z363: 0.26553844 | AA363: -1.7867758

Sheet Sheet4
A1: company | B1: Наименование | C1: year | D1: Дивиденд | E1: industry | F1: sum | G1: peer_sum | H1: payout | I1: payout_ratio | J1: abs | K1: pabs | L1: inc | M1: inc_ratio | N1: dec | O1: dec_ratio | P1: Size | Q1: Tangibility | R1: Sales_growth | S1: REBE | T1: ROA | U1: Leverage | V1: Psize | W1: PTangibility | X1: PSales_growth | Y1: PREBE | Z1: PROA | AA1: PLeverage
A2: GAZP | B2: GAZP IV кв. 2024 | C2: 2024 | D2: 0 | E2: 1 | F2: 0 | G2: 214.65 | H2: 0 | I2: 0.83333333 | J2: 0 | K2: 0.033213968 | L2: 0 | M2: 0.66666667 | N2: 0 | O2: 0.16666667 | P2: 31.055227 | Q2: 0.67690981 | R2: 0.25438004 | S2: 0.88491057 | T2: 0.04439204 | U2: 0.73819835 | V2: 28.89571 | W2: 0.51199198 | X2: 0.17118061 | Y2: 0.79852548 | Z2: 0.12177692 | AA2: 0.85190113
A3: GAZP | B3: GAZP IV кв. 2023 | C3: 2023 | D3: 0 | E3: 1 | F3: 0 | G3: 195.35 | H3: 0 | I3: 0.83333333 | J3: -1 | K3: 0.07318505 | L3: 0 | M3: 0.5 | N3: 1 | O3: 0.33333333 | P3: 30.988397 | Q3: 0.64206898 | R3: -0.26830096 | S3: 0.88690206 | T3: -0.021263586 | U3: 0.74522866 | V3: 28.950488 | W3: 0.47348976 | X3: -0.037500665 | Y3: 0.80302193 | Z3: 0.11841775 | AA3: 0.83818778
A4: GAZP | B4: GAZP IV кв. 2022 | C4: 2022 | D4: 51.03 | E4: 1 | F4: 51.03 | G4: 240.50333 | H4: 1 | I4: 0.83333333 | J4: 1 | K4: 0.59952004 | L4: 1 | M4: 0.5 | N4: 0 | O4: 0.16666667 | P4: 30.894064 | Q4: 0.66665802 | R4: 0.13988357 | S4: 0.9197466 | T4: 0.04933207 | U4: 0.58878604 | V4: 28.005023 | W4: 0.45949876 | X4: 0.1038114 | Y4: 0.78172804 | Z4: 0.12952165 | AA4: 0.8837483
A5: GAZP | B5: GAZP IV кв. 2021 | C5: 2021 | D5: 0 | E5: 1 | F5: 0 | G5: 82.756667 | H5: 0 | I5: 0.83333333 | J5: -1 | K5: 1.2307909 | L5: 0 | M5: 0.83333333 | N5: 1 | O5: 0 | P5: 30.928606 | Q5: 0.61646121 | R5: 0.62006761 | S5: 0.92570438 | T5: 0.08567901 | U5: 0.60359905 | V5: 28.588015 | W5: 0.54592305 | X5: 0.71962064 | Y5: 0.78164523 | Z5: 0.12893486 | AA5: 1.1281548
A6: GAZP | B6: GAZP IV кв. 2020 | C6: 2020 | D6: 12.55 | E6: 1 | F6: 12.55 | G6: 54.073333 | H6: 1 | I6: 0.83333333 | J6: -0.17650919 | K6: -0.29877017 | L6: 0 | M6: 0.33333333 | N6: 1 | O6: 0.5 | P6: 30.781712 | Q6: 0.68957552 | R6: -0.17469058 | S6: 0.92655943 | T6: 0.0071806644 | U6: 0.57734601 | V6: 28.624109 | W6: 0.5371219 | X6: -0.27049471 | Y6: 0.74822584 | Z6: 0.032136749 | AA6: 1.2967729
A7: GAZP | B7: GAZP IV кв. 2019 | C7: 2019 | D7: 15.24 | E7: 1 | F7: 15.24 | G7: 112.14333 | H7: 1 | I7: 0.83333333 | J7: -0.082480433 | K7: 0.24288945 | L7: 0 | M7: 0.5 | N7: 1 | O7: 0.16666667 | P7: 30.716701 | Q7: 0.67892385 | R7: -0.068645653 | S7: 0.94282055 | T7: 0.059472199 | U7: 0.49718231 | V7: 28.572217 | W7: 0.51462951 | X7: 0.025367391 | Y7: 0.82043004 | Z7: 0.16320282 | AA7: 0.95146752
A8: GAZP | B8: GAZP IV кв. 2018 | C8: 2018 | D8: 16.61 | E8: 1 | F8: 16.61 | G8: 64.588333 | H8: 1 | I8: 0.83333333 | J8: 1.0659204 | K8: 0.58403361 | L8: 1 | M8: 0.66666667 | N8: 0 | O8: 0 | P8: 30.666476 | Q8: 0.66358203 | R8: 0.25633934 | S8: 0.95895668 | T8: 0.078311239 | U8: 0.5106133 | V8: 28.458498 | W8: 0.50857093 | X8: 0.36447021 | Y8: 0.75475667 | Z8: 0.12546632 | AA8: 0.92459536
A9: GAZP | B9: GAZP IV кв. 2017 | C9: 2017 | D9: 8.04 | E9: 1 | F9: 8.04 | G9: 46.836667 | H9: 1 | I9: 0.83333333 | J9: 0 | K9: 0.2941553 | L9: 0 | M9: 0.83333333 | N9: 0 | O9: 0 | P9: 30.534571 | Q9: 0.68782484 | R9: 0.071197573 | S9: 0.96041191 | T9: 0.043625085 | U9: 0.51793923 | V9: 28.340294 | W9: 0.5242558 | X9: 0.16368052 | Y9: 0.73280408 | Z9: 0.077823093 | AA9: 0.97472196
A10: GAZP | B10: GAZP IV кв. 2016 | C10: 2016 | D10: 8.04 | E10: 1 | F10: 8.04 | G10: 39.715 | H10: 1 | I10: 0.83333333 | J10: 0.019011407 | K10: 0.12024418 | L10: 1 | M10: 0.5 | N10: 0 | O10: 0.16666667 | P10: 30.459455 | Q10: 0.67987406 | R10: 0.0062129136 | S10: 0.96184328 | T10: 0.058703285 | U10: 0.47869044 | V10: 28.279917 | W10: 0.50976916 | X10: 0.012025011 | Y10: 0.68181067 | Z10: 0.10464156 | AA10: 1.0228333
A11: GAZP | B11: GAZP IV кв. 2015 | C11: 2015 | D11: 7.89 | E11: 1 | F11: 7.89 | G11: 35.635 | H11: 1 | I11: 0.83333333 | J11: 0.095833333 | K11: 0.14170092 | L11: 1 | M11: 0.66666667 | N11: 0 | O11: 0.16666667 | P11: 30.467291 | Q11: 0.6453117 | R11: 0.086497916 | S11: 0.94994687 | T11: 0.049966568 | U11: 0.56231155 | V11: 28.027872 | W11: 0.5715191 | X11: 0.11349517 | Y11: 0.93141876 | Z11: 0.083332631 | AA11: -1.2671068
A12: GAZP | B12: GAZP IV кв. 2014 | C12: 2014 | D12: 7.2 | E12: 1 | F12: 7.2 | G12: 30.623333 | H12: 1 | I12: 0.83333333 | J12: 0 | K12: 0.11887241 | L12: 0 | M12: 0.66666667 | N12: 0 | O12: 0.16666667 | P12: 30.350833 | Q12: 0.65559075 | R12: 0.064733003 | S12: 0.94814853 | T12: 0.010987182 | U12: 0.49974689 | V12: 28.372329 | W12: 0.62176756 | X12: 0.16466401 | Y12: 0.98195602 | Z12: 0.071375294 | AA12: 0.86783657
A13: GAZP | B13: GAZP IV кв. 2012 | C13: 2012 | D13: 5.99 | E13: 1 | F13: 5.99 | G13: 19.001667 | H13: 1 | I13: 0.83333333 | J13: -0.33221851 | K13: 0.076735506 | L13: 0 | M13: 0.66666667 | N13: 1 | O13: 0.16666667 | P13: 30.12159 | Q13: 0.64785399 | R13: 0.027457091 | S13: 0.93903491 | T13: 0.10540944 | U13: 0.38696801 | V13: 27.941602 | W13: 0.6129454 | X13: 0.039420032 | Z13: 0.12618572 | AA13: 0.50988452
A14: LKOH | B14: LKOH IV кв. 2025 | C14: 2025 | D14: 397 | E14: 1 | F14: 397 | G14: 11.59 | H14: 1 | I14: 0.5 | J14: -0.62369668 | K14: -0.5190168 | L14: 0 | M14: 0 | N14: 1 | O14: 0.66666667 | P14: 29.331108 | Q14: 0.68588587 | R14: -0.56298308 | S14: 1.1230089 | T14: -0.14364114 | U14: 0.50958002 | V14: 28.648938 | W14: 0.47597261 | X14: -0.084693664 | Y14: 0.92840826 | Z14: 0.060424107 | AA14: 0.43679759
A15: LKOH | B15: LKOH IV кв. 2024 | C15: 2024 | D15: 1055 | E15: 1 | F15: 1055 | G15: 38.816667 | H15: 1 | I15: 0.66666667 | J15: 0.11640212 | K15: 0.013813615 | L15: 1 | M15: 0.5 | N15: 0 | O15: 0.16666667 | P15: 29.859165 | Q15: 0.54042765 | R15: 0.087440906 | S15: 0.82896494 | T15: 0.095236359 | U15: 0.34686712 | V15: 29.134922 | W15: 0.53928841 | X15: 0.20456844 | Y15: 0.81251189 | Z15: 0.11160806 | AA15: 0.93016738
A16: LKOH | B16: LKOH IV кв. 2021 | C16: 2021 | D16: 340 | E16: 1 | F16: 340 | G16: 26.09 | H16: 1 | I16: 0.66666667 | J16: 0.31274131 | K16: 1.0120007 | L16: 1 | M16: 0.66666667 | N16: 0 | O16: 0.16666667 | P16: 29.557421 | Q16: 0.62101761 | R16: 0.67307539 | S16: 0.94628607 | T16: 0.120643 | U16: 0.51768069 | V16: 28.862252 | W16: 0.54501177 | X16: 0.70901908 | Y16: 0.77752889 | Z16: 0.12194206 | AA16: 1.1453385
A17: LKOH | B17: LKOH IV кв. 2020 | C17: 2020 | D17: 259 | E17: 1 | F17: 259 | G17: 12.998333 | H17: 1 | I17: 0.83333333 | J17: -0.52214022 | K17: -0.241165 | L17: 0 | M17: 0.33333333 | N17: 1 | O17: 0.5 | P17: 29.421376 | Q17: 0.7117446 | R17: -0.28080295 | S17: 0.93398101 | T17: 0.0027864171 | U17: 0.4504765 | V17: 28.850832 | W17: 0.53342706 | X17: -0.25280932 | Y17: 0.74698891 | Z17: 0.032869124 | AA17: 1.3179179
A18: LKOH | B18: LKOH IV кв. 2019 | C18: 2019 | D18: 542 | E18: 1 | F18: 542 | G18: 24.35 | H18: 1 | I18: 0.83333333 | J18: 1.168 | K18: 0.03447604 | L18: 1 | M18: 0.33333333 | N18: 0 | O18: 0.33333333 | P18: 29.413916 | Q18: 0.67697548 | R18: -0.024221713 | S18: 1.057806 | T18: 0.1099747 | U18: 0.4966972 | V18: 28.789348 | W18: 0.51495424 | X18: 0.017963401 | Y18: 0.80126581 | Z18: 0.15478573 | AA18: 0.95154837
A19: LKOH | B19: LKOH IV кв. 2018 | C19: 2018 | D19: 250 | E19: 1 | F19: 250 | G19: 25.69 | H19: 1 | I19: 0.83333333 | J19: 0.1627907 | K19: 0.73455523 | L19: 1 | M19: 0.66666667 | N19: 0 | O19: 0 | P19: 29.377152 | Q19: 0.66798828 | R19: 0.35359412 | S19: 0.97302141 | T19: 0.11335429 | U19: 0.40722853 | V19: 28.673386 | W19: 0.50783656 | X19: 0.34826108 | Y19: 0.75241255 | Z19: 0.11962581 | AA19: 0.94182616
A20: LKOH | B20: LKOH IV кв. 2017 | C20: 2017 | D20: 215 | E20: 1 | F20: 215 | G20: 12.343333 | H20: 1 | I20: 0.83333333 | J20: 0.1025641 | K20: 0.27706128 | L20: 1 | M20: 0.66666667 | N20: 0 | O20: 0 | P20: 29.284708 | Q20: 0.68408303 | R20: 0.13576696 | S20: 1.02457 | T20: 0.082106552 | U20: 0.49731163 | V20: 28.548605 | W20: 0.52487944 | X20: 0.15291895 | Y20: 0.72211107 | Z20: 0.071409515 | AA20: 0.97815989
A21: LKOH | B21: LKOH IV кв. 2016 | C21: 2016 | D21: 195 | E21: 1 | F21: 195 | G21: 8.555 | H21: 1 | I21: 0.83333333 | J21: 0.10169492 | K21: 0.1064636 | L21: 1 | M21: 0.5 | N21: 0 | O21: 0.16666667 | P21: 29.243389 | Q21: 0.67628856 | R21: -0.09079848 | S21: 1.0232958 | T21: 0.041382403 | U21: 0.55365397 | V21: 28.482595 | W21: 0.51036674 | X21: 0.03142729 | Y21: 0.66952017 | Z21: 0.10810574 | AA21: 1.0103394
